{"uuid": "dbbdcfbd-7859-429e-9d74-aa7b87ca3d46", "children": ["5b8baacd-7f9f-433a-a46f-344d34a67924"], "befores": [{"name": "driver", "status": "broken", "statusDetails": {"message": "selenium.common.exceptions.WebDriverException: Message: An unknown server-side error occurred while processing the command. Original error: Error getting device API level. Original error: Error executing adbExec. Original error: 'Command '/Users/yaroslav.petryk/Library/Android/sdk/platform-tools/adb -P 5037 -s 18241FDF600BJ0 shell getprop ro.build.version.sdk' exited with code 1'; Command output: adb: device unauthorized.\nThis adb server's $ADB_VENDOR_KEYS is not set\nTry 'adb kill-server' if that seems wrong.\nOtherwise check for a confirmation dialog on your device.\n\nStacktrace:\nUnknownError: An unknown server-side error occurred while processing the command. Original error: Error getting device API level. Original error: Error executing adbExec. Original error: 'Command '/Users/yaroslav.petryk/Library/Android/sdk/platform-tools/adb -P 5037 -s 18241FDF600BJ0 shell getprop ro.build.version.sdk' exited with code 1'; Command output: adb: device unauthorized.\nThis adb server's $ADB_VENDOR_KEYS is not set\nTry 'adb kill-server' if that seems wrong.\nOtherwise check for a confirmation dialog on your device.\n\n    at getResponseForW3CError (/Applications/Appium Server GUI.app/Contents/Resources/app/node_modules/appium/node_modules/appium-base-driver/lib/protocol/errors.js:804:9)\n    at asyncHandler (/Applications/Appium Server GUI.app/Contents/Resources/app/node_modules/appium/node_modules/appium-base-driver/lib/protocol/protocol.js:380:37)\n", "trace": "  File \"/Library/Frameworks/Python.framework/Versions/3.10/lib/python3.10/site-packages/pluggy/_callers.py\", line 39, in _multicall\n    res = hook_impl.function(*args)\n  File \"/Library/Frameworks/Python.framework/Versions/3.10/lib/python3.10/site-packages/_pytest/fixtures.py\", line 1128, in pytest_fixture_setup\n    result = call_fixture_func(fixturefunc, request, kwargs)\n  File \"/Library/Frameworks/Python.framework/Versions/3.10/lib/python3.10/site-packages/_pytest/fixtures.py\", line 900, in call_fixture_func\n    fixture_result = next(generator)\n  File \"/Users/yaroslav.petryk/Desktop/projects/testrail_android_with_trcli/tests/conftest.py\", line 18, in driver\n    appium_driver = webdriver.Remote(url, capabilities)\n  File \"/Library/Frameworks/Python.framework/Versions/3.10/lib/python3.10/site-packages/appium/webdriver/webdriver.py\", line 257, in __init__\n    super().__init__(\n  File \"/Library/Frameworks/Python.framework/Versions/3.10/lib/python3.10/site-packages/selenium/webdriver/remote/webdriver.py\", line 272, in __init__\n    self.start_session(capabilities, browser_profile)\n  File \"/Library/Frameworks/Python.framework/Versions/3.10/lib/python3.10/site-packages/appium/webdriver/webdriver.py\", line 346, in start_session\n    response = self.execute(RemoteCommand.NEW_SESSION, w3c_caps)\n  File \"/Library/Frameworks/Python.framework/Versions/3.10/lib/python3.10/site-packages/selenium/webdriver/remote/webdriver.py\", line 429, in execute\n    self.error_handler.check_response(response)\n  File \"/Library/Frameworks/Python.framework/Versions/3.10/lib/python3.10/site-packages/selenium/webdriver/remote/errorhandler.py\", line 243, in check_response\n    raise exception_class(message, screen, stacktrace)\n"}, "start": 1694590687326, "stop": 1694590691998}], "start": 1694590687326, "stop": 1694590692135}